Workbook

Sheet Hoja 1
A2: NOMBRE | B2: CARGO | C2: ESTADO | D2: NACIONALIDAD | E2: CUMPLEAÑOS | F2: IMAGEN | G2: PASSAPORTO | H2: SCADENZA PASSAPORTO | I2: CARTA DI IDENTITA | J2: SCADENZA CARTA IDENTITA | K2: PERMESSO DI SOGGIORNO | L2: SCADENZA SOGGIORNO | M2: PATENTE | N2: SCADENZA PATENTE | O2: TRADUZIONE PATENTE | P2: SCADENZA TRADUZIONE | Q2: C. FISCALE | R2: SCADENZA C. FISCALE | S2: CONTRATO | T2: SCADENZA CONTRATO | U2: TELEFONO | V2: CORREO ELECTRONICO | W2: DIRECCION | X2: ÁREA | Y2: Correo_Supervisor_Asignado | Z2: Id_Trabajador | AA2: PERMISO UNIVEX | AB2: CU 2024 | AC2: DIMISSIONE | AD2: RESPONSIVA
A3: CARLOS GAMONAL | B3: COO / DIRECTOR OPERACIONES | C3: ACTIVO | D3: PERU | E3: 26791 | F3: Hoja 1_Images/G001.IMAGEN.003525.png | I3: Hoja 1_Files_/CARLOS GAMONAL.CARTA DI IDENTITA.165615.pdf | J3: 48034 | M3: Hoja 1_Files_/CARLOS GAMONAL.PATENTE.165615.pdf | N3: 47245 | Q3: Hoja 1_Files_/CARLOS GAMONAL.C. FISCALE.165615.pdf | S3: Hoja 1_Files_/CARLOS GAMONAL.CONTRATO.141539.pdf | U3: 3201499727 | V3: carlos.ga@gamonaltrasporti.com | W3: Via Domenico Cimarosa, 5, 20096 Pioltello MI, Italia | X3: UNIVEX/DHL | Z3: G001 | AB3: Hoja 1_Files_/G001.CU 2024.120944.pdf
A4: EMERSON GAMONAL | B4: CEO / DIRECTOR GENERAL | C4: ACTIVO | D4: PERUANO | E4: 26926 | F4: Hoja 1_Images/G002.IMAGEN.003550.png | K4: Hoja 1_Files_/G002.PERMESSO DI SOGGIORNO.220721.pdf | L4: 46311 | M4: Hoja 1_Files_/EMERSON GAMONAL.PATENTE.112542.pdf | N4: 47500 | Q4: Hoja 1_Files_/EMERSON GAMONAL.C. FISCALE.112542.pdf | R4: 47483 | S4: Hoja 1_Files_/EMERSON GAMONAL.CONTRATO.180441.pdf | T4: 47483 | U4: 3519033631 | V4: emerson.gs@gamonaltrasporti.com | W4: Via Domenico Cimarosa, 5, 20096 Pioltello MI, Italia | X4: UNIVEX/DHL | Z4: G002 | AB4: Hoja 1_Files_/G002.CU 2024.120922.pdf
A5: YAN GAMONAL | B5: DIRECTOR DE DESARROLLO | C5: ACTIVO | D5: PERUANA | E5: 35819 | F5: Hoja 1_Images/G003.IMAGEN.003537.png | G5: Hoja 1_Files_/G003.PASSAPORTO.220031.pdf | H5: 49509 | I5: Hoja 1_Files_/YAN GAMONAL.CARTA DI IDENTITA.053659.pdf | J5: 48001 | M5: Hoja 1_Files_/YAN GAMONAL.PATENTE.053700.pdf | N5: 49039 | U5: +51965132485 | V5: yan.gs@gamonaltrasporti.com | W5: Urb. Santa Beatriz Mz M Lt8 Callao | X5: UNIVEX/DHL | Z5: G003
A6: NATALIA PLUA | B6: SUPERVISORA GENERAL | C6: ACTIVO | D6: ECUATORIANA | E6: 36491 | F6: Hoja 1_Images/G004.IMAGEN.225042.png | I6: Hoja 1_Files_/NATALIA PLUA.CARTA DI IDENTITA.181551.pdf | J6: 47449 | M6: Hoja 1_Files_/NATALIA PLUA.PATENTE.181551.pdf | N6: 47449 | Q6: Hoja 1_Files_/NATALIA PLUA.C. FISCALE.181550.pdf | R6: 46713 | S6: Hoja 1_Files_/NATALIA PLUA.CONTRATO.181552.pdf | T6: 47483 | U6: 3286071390 | V6: autista.gamonaltrasporti@gmail.com | W6: Via Magenta, 38, 20017 Rho MI, Italia | X6: UNIVEX/DHL | Z6: G004 | AA6: Hoja 1_Files_/G004.PERMISO UNIVEX.164135.pdf | AB6: Hoja 1_Files_/G004.CU 2024.180719.pdf
A7: LUIS POMA | B7: SUPERVISOR | C7: INACTIVO | D7: PERU | E7: 32389 | F7: Hoja 1_Images/G005.IMAGEN.225057.png | I7: Hoja 1_Images/G005.CARTA DI IDENTITA.164951.jpg | J7: 46999 | K7: Hoja 1_Images/G005.PERMESSO DI SOGGIORNO.164951.jpg | L7: 46563 | M7: Hoja 1_Files_/LUIS POMA.PATENTE.182132.pdf | P7: 46003 | Q7: Hoja 1_Images/G005.C. FISCALE.164952.jpg | R7: 45989 | S7: Hoja 1_Files_/LUIS POMA.CONTRATO.182133. CONTRATO LUIS IND.pdf | U7: 3343849127 | V7: luizpoma.lp@gmail.com | W7: Via Moneta Teodoro, 1, 23876 Monticello LC, Italia | X7: INACTIVO | Z7: G005 | AA7: Hoja 1_Files_/G005.PERMISO UNIVEX.164204.pdf | AB7: Hoja 1_Files_/G005.CU 2024.180737.pdf
A8: MARTIN RODRIGUEZ | B8: SUPERVISOR | C8: ACTIVO | D8: PERU | E8: 33957 | F8: Hoja 1_Images/G006.IMAGEN.202138.png | I8: Hoja 1_Files_/MARTIN RODRIGUEZ.CARTA DI IDENTITA.192726.pdf | M8: Hoja 1_Files_/MARTIN RODRIGUEZ.PATENTE.182705. Patente MARTIN.pdf | Q8: Hoja 1_Files_/MARTIN RODRIGUEZ.C. FISCALE.182705. Codice Fiscale MARTIN.pdf | S8: Hoja 1_Files_/MARTIN RODRIGUEZ.CONTRATO.182707.pdf | U8: 3519584517 | V8: gamonaltrasporti.spedizione@gmail.com | W8: Via Montebello, 26, 20121 Milano MI, Italia | X8: DHL | Y8: gamonaltrasporti.spedizione@gmail.com | Z8: G006 | AA8: Hoja 1_Files_/G006.PERMISO UNIVEX.164420.pdf | AB8: Hoja 1_Files_/G006.CU 2024.181136.pdf
A9: MARVIN CASTILLO | B9: SUPERVISOR | C9: ACTIVO | D9: PERU | E9: 33356 | F9: Hoja 1_Images/G008.IMAGEN.164019.png | I9: Hoja 1_Files_/MARVIN CASTILLO.CARTA DI IDENTITA.183321. Carta di identita MARVIN.pdf | J9: 46871 | M9: Hoja 1_Files_/MARVIN CASTILLO.PATENTE.183320. Patente MARVIN.pdf | Q9: Hoja 1_Files_/MARVIN CASTILLO.C. FISCALE.183320. Codice fiscale MARVIN.pdf | S9: Hoja 1_Files_/MARVIN CASTILLO.CONTRATO.183322. CONTRATO MARVIN.pdf | U9: 3338356449 | V9: marvin28abril@gmail.com | W9: Viale Domenico Cimarosa, 5 pioltello | X9: UNIVEX | Y9: marvin28abril@gmail.com | Z9: G008 | AA9: Hoja 1_Files_/G008.PERMISO UNIVEX.164235.pdf | AB9: Hoja 1_Files_/G008.CU 2024.180159.pdf
A10: CESAR PLUA | B10: AUTISTA | C10: ACTIVO | D10: ECUATORIANO | E10: 20942 | F10: Hoja 1_Images/G007.IMAGEN.164006.png | I10: Hoja 1_Files_/CESAR PLUA.CARTA DI IDENTITA.183020. Carta di identita CESAR.pdf | J10: 47605 | K10: Hoja 1_Files_/G007.PERMESSO DI SOGGIORNO.103700.S_CESAR.pdf | L10: 48767 | M10: Hoja 1_Files_/CESAR PLUA.PATENTE.183020. Patente CÉSAR.pdf | N10: 46318 | Q10: Hoja 1_Files_/CESAR PLUA.C. FISCALE.183020. Codice fiscale CESAR.pdf | R10: 45926 | U10: 3493471721 | W10: Viale Palmiro Togliatti, 114, 20089 Rozzano MI, Italia | X10: UNIVEX | Y10: marvin28abril@gmail.com | Z10: G007 | AA10: Hoja 1_Files_/G007.PERMISO UNIVEX.164219.pdf | AB10: Hoja 1_Files_/G007.CU 2024.180700.pdf
A11: DOMINICK LEON | B11: AUTISTA | C11: INACTIVO | D11: PERUANO | E11: 33622 | F11: Hoja 1_Images/DOMINICK LEON.IMAGEN.055121.png | I11: Hoja 1_Files_/DOMINICK LEON.CARTA DI IDENTITA.183612. Carta di identita DOMINICK.pdf | M11: Hoja 1_Files_/DOMINICK LEON.PATENTE.183612. Patente DOMINI.pdf | Q11: Hoja 1_Files_/DOMINICK LEON.C. FISCALE.183612. Tessera DOMINICK.pdf | U11: 3277908045 | W11: Via Aldo Moro, 9, 24058 Sola BG, Italia | X11: INACTIVO | Z11: G009
A12: IVAN HERRERA | B12: AUTISTA | C12: INACTIVO | D12: PERUANO | E12: 35713 | F12: Hoja 1_Images/IVAN HERRERA.IMAGEN.055145.png | I12: Hoja 1_Files_/IVAN HERRERA.CARTA DI IDENTITA.183921. Carta di identita IVAN.pdf | M12: Hoja 1_Files_/IVAN HERRERA.PATENTE.183921. Patente IVAN.pdf | Q12: Hoja 1_Files_/IVAN HERRERA.C. FISCALE.183921. Tessera IVAN.pdf | S12: Hoja 1_Files_/IVAN HERRERA.CONTRATO.183923. CONTRATO IVAN IND.pdf | U12: 3516813140 | W12: Via Milano, 7, 23871 Lomagna LC, Italia | X12: INACTIVO | Z12: G010 | AB12: Hoja 1_Files_/G010.CU 2024.180627.pdf
A13: ROMARIO QUISPE | B13: AUTISTA | C13: ACTIVO | D13: PERUANO | E13: 34943 | F13: Hoja 1_Images/G011.IMAGEN.230301.png | I13: Hoja 1_Files_/ROMARIO QUISPE.CARTA DI IDENTITA.184248. Carta di identita ROMARIO.pdf | M13: Hoja 1_Files_/ROMARIO QUISPE.PATENTE.150924.pdf | S13: Hoja 1_Files_/ROMARIO QUISPE.CONTRATO.010947.pdf | U13: 3926274483 | V13: quispehinostrozaromario1995@gmail.com | W13: Via Rogoredo, 7, 20138 Milano MI, Italia | X13: UNIVEX | Y13: marvin28abril@gmail.com | Z13: G011 | AA13: Hoja 1_Files_/G011.PERMISO UNIVEX.164432.pdf | AB13: Hoja 1_Files_/G011.CU 2024.180940.pdf | AC13: Hoja 1_Files_/G011.DIMISSIONE.171911.pdf
A14: YHEYSON ACHAICA | B14: AUTISTA | C14: INACTIVO | D14: PERUANO | E14: 36025 | F14: Hoja 1_Images/YHEYSON ACHAICA.IMAGEN.055215.png | I14: Hoja 1_Files_/YHEYSON ACHAICA.CARTA DI IDENTITA.185200. Carta di identita YHEYSON.pdf | M14: Hoja 1_Files_/YHEYSON ACHAICA.PATENTE.185200. Patente YHEYSON.pdf | Q14: Hoja 1_Files_/YHEYSON ACHAICA.C. FISCALE.185200. Codice fiscale YHEYSON.pdf | S14: Hoja 1_Files_/YHEYSON ACHAICA.CONTRATO.230832.pdf | U14: 3513498499 | W14: Via F. Cilea, 20096 Pioltello MI, Italia | X14: INACTIVO | Z14: G012 | AB14: Hoja 1_Files_/G012.CU 2024.175843.pdf
A15: ADOLFO ROSALES | B15: AUTISTA | C15: INACTIVO | D15: SALVADOREÑO | E15: 30938 | F15: Hoja 1_Images/ADOLFO ROSALES.IMAGEN.055233.png | I15: Hoja 1_Files_/ADOLFO ROSALES.CARTA DI IDENTITA.185314. Carta di identita ADOLFO.pdf | M15: Hoja 1_Files_/ADOLFO ROSALES.PATENTE.185314. Patente ADOLFO.pdf | Q15: Hoja 1_Files_/ADOLFO ROSALES.C. FISCALE.185314. Codice Fiscale ADOLFO.pdf | S15: Hoja 1_Files_/ADOLFO ROSALES.CONTRATO.185316.pdf | U15: 3505307941 | W15: Via G. Matteotti, 10, 20019 Settimo Milanese MI, Italia | X15: INACTIVO | Z15: G013 | AB15: Hoja 1_Files_/G013.CU 2024.181721.pdf
A16: ALONSO TAMARA | B16: AUTISTA | C16: ACTIVO | D16: PERU | E16: 33799 | F16: Hoja 1_Images/G014.IMAGEN.225829.png | K16: Hoja 1_Files_/G014.PERMESSO DI SOGGIORNO.150250.pdf | L16: 46227 | M16: Hoja 1_Files_/G014.PATENTE.150250.pdf | N16: 48458 | O16: Hoja 1_Files_/G014.TRADUZIONE PATENTE.150250.pdf | P16: 45944 | Q16: Hoja 1_Files_/ALONSO TAMARA.C. FISCALE.104936.pdf | S16: Hoja 1_Files_/G014.CONTRATO.155159.pdf | U16: 3312380816 | V16: 14jatg07@gmail.com | W16: Via F. Cilea, 4, 20096 Pioltello MI, Italia | X16: DHL | Y16: gamonaltrasporti.spedizione@gmail.com | Z16: G014 | AD16: Hoja 1_Files_/G014.RESPONSIVA.073454.pdf
A17: EDWARD GUERRERO | B17: AUTISTA | C17: INACTIVO | D17: PERUANO | E17: 33066 | F17: Hoja 1_Images/G015.IMAGEN.225145.png | I17: Hoja 1_Files_/EDWARD GUERRERO.CARTA DI IDENTITA.185751. Carta di identita EDWARD.pdf | M17: Hoja 1_Files_/EDWARD GUERRERO.PATENTE.185751. Patente EDWARD.pdf | Q17: Hoja 1_Files_/EDWARD GUERRERO.C. FISCALE.185752. Codice fiscale EDWARD.pdf | S17: Hoja 1_Files_/EDWARD GUERRERO.CONTRATO.150951.pdf | U17: 3514032510 | W17: Viale Fratelli Cervi, 19, 20098 San Giuliano Milanese MI, Italia | X17: INACTIVO | Z17: G015 | AA17: Hoja 1_Files_/G015.PERMISO UNIVEX.164250.pdf | AB17: Hoja 1_Files_/G015.CU 2024.180554.pdf
A18: JUAN TEJADA | B18: AUTISTA | C18: ACTIVO | D18: SALVADOREÑO | E18: 36795 | F18: Hoja 1_Images/G016.IMAGEN.193310.png | I18: Hoja 1_Files_/JUAN TEJADA.CARTA DI IDENTITA.190103. Carta di identita JUAN.pdf | M18: Hoja 1_Files_/JUAN TEJADA.PATENTE.190103. Patente JUAN_.pdf | Q18: Hoja 1_Files_/JUAN TEJADA.C. FISCALE.190103. Codice fiscale JUAN.pdf | S18: Hoja 1_Files_/G016.CONTRATO.110538.25 -file.pdf | U18: 3517498714 | W18: Viale Leonardo da Vinci, 130, 20090 Trezzano sul Naviglio MI, Italia | X18: UNIVEX | Y18: marvin28abril@gmail.com | Z18: G016 | AA18: Hoja 1_Files_/G016.PERMISO UNIVEX.164306.pdf | AB18: Hoja 1_Files_/G016.CU 2024.181746.pdf
A19: JURGEN PALIZA | B19: AUTISTA | C19: ACTIVO | D19: PERU | E19: 30079 | F19: Hoja 1_Images/G017.IMAGEN.164202.png | I19: Hoja 1_Files_/G017.CARTA DI IDENTITA.111820.pdf | J19: 46756 | K19: Hoja 1_Files_/G017.PERMESSO DI SOGGIORNO.111824.pdf | L19: 46096 | M19: Hoja 1_Files_/G017.PATENTE.111820.pdf | N19: 47534 | Q19: Hoja 1_Files_/G017.C. FISCALE.111820.pdf | R19: 47102 | S19: Hoja 1_Files_/JURGEN PALIZA.CONTRATO.192901.pdf | U19: 3533506252 | V19: jurgen2000pv@gmail.com | W19: Via Alcide de Gasperi, 1, 20900 Monza MB, Italia | X19: UNIVEX | Y19: marvin28abril@gmail.com | Z19: G017 | AA19: Hoja 1_Files_/G017.PERMISO UNIVEX.164446.pdf | AB19: Hoja 1_Files_/G017.CU 2024.180641.pdf | AD19: Hoja 1_Files_/G017.RESPONSIVA.073744.pdf
A20: DUMINDA HADUN | B20: AUTISTA | C20: INACTIVO | D20: SRI LANKA | E20: 27084 | F20: Hoja 1_Images/DUMINDA HADUN.IMAGEN.055805.png | I20: Hoja 1_Files_/DUMINDA HADUN.CARTA DI IDENTITA.190633. CARTA DI IDENTITA DUMINDA.pdf | M20: Hoja 1_Files_/DUMINDA HADUN.PATENTE.190634. PATENTE DUMINDA.pdf | Q20: Hoja 1_Files_/DUMINDA HADUN.C. FISCALE.190634. TESSERA SANITARIA DUMINDA.pdf | S20: Hoja 1_Files_/DUMINDA HADUN.CONTRATO.190635.pdf | U20: 3312025402 | W20: Via Primo Maggio, 2, 20872 Porto d'Adda MB, Italia | X20: INACTIVO | Z20: G018 | AB20: Hoja 1_Files_/G018.CU 2024.180612.pdf
A21: SHANTHA NEELAPPAGE | B21: AUTISTA | C21: INACTIVO | D21: SRI LANKA | E21: 24961 | F21: Hoja 1_Images/SHANTHA NEELAPPAGE.IMAGEN.234228.png | I21: Hoja 1_Files_/SHANTHA NEELAPPAGE.CARTA DI IDENTITA.234228.pdf | M21: Hoja 1_Files_/SHANTHA NEELAPPAGE.PATENTE.234228.pdf | Q21: Hoja 1_Files_/SHANTHA NEELAPPAGE.C. FISCALE.234229.pdf | S21: Hoja 1_Files_/SHANTHA NEELAPPAGE.CONTRATO.234229.pdf | U21: 3279807682 | W21: Cascina degli Angeli, 5, 27020 Dorno PV, Italia | X21: INACTIVO | Z21: G019
A22: DIEGO MOLINA | B22: AUTISTA | C22: ACTIVO | D22: PERU | E22: 32570 | F22: Hoja 1_Images/G020.IMAGEN.193323.png | I22: Hoja 1_Files_/DIEGO MOLINA.CARTA DI IDENTITA.160435.pdf | Q22: Hoja 1_Files_/DIEGO MOLINA.C. FISCALE.160435.pdf | S22: Hoja 1_Files_/G020.CONTRATO.044700.pdf | U22: 3382692929 | V22: Alonsomolina0389@gmail.com | W22: Via Metastasio, 20123 Milano MI, Italia | X22: UNIVEX | Y22: marvin28abril@gmail.com | Z22: G020 | AA22: Hoja 1_Files_/G020.PERMISO UNIVEX.164325.pdf
A23: ANTONIO RIVERA | B23: AUTISTA | C23: ACTIVO | D23: PERU | E23: 26901 | F23: Hoja 1_Images/G021.IMAGEN.193346.png | I23: Hoja 1_Files_/ANTONIO RIVERA.CARTA DI IDENTITA.153916.pdf | M23: Hoja 1_Files_/ANTONIO RIVERA.PATENTE.153916.pdf | Q23: Hoja 1_Files_/ANTONIO RIVERA.C. FISCALE.111357.pdf | S23: Hoja 1_Files_/G021.CONTRATO.044757.pdf | U23: 3509340221 | V23: Antonio.rivera152535@gmail.com | W23: Via Leonardo Da Vinci, 49, 20092 Cinisello Balsamo MI, Italia | X23: UNIVEX | Y23: marvin28abril@gmail.com | Z23: G021 | AA23: Hoja 1_Files_/G021.PERMISO UNIVEX.164339.pdf
A24: EDUARDO SANTA CRUZ | B24: AUTISTA | C24: INACTIVO | D24: PERU | E24: 36052 | F24: Hoja 1_Images/G022.IMAGEN.230747.png | I24: Hoja 1_Files_/EDUARDO SANTA CRUZ.CARTA DI IDENTITA.213311.pdf | M24: Hoja 1_Files_/EDUARDO SANTA CRUZ.PATENTE.213311.pdf | U24: 38061122 | X24: INACTIVO | Z24: G022
A25: ELIZANGELA CHUMBE | B25: AUTISTA | C25: ACTIVO | D25: PERU | E25: 30599 | F25: Hoja 1_Images/G023.IMAGEN.164945.png | G25: Hoja 1_Images/G023.PASSAPORTO.131858.jpg | H25: 46604 | I25: Hoja 1_Files_/G023.CARTA DI IDENTITA.131853.pdf | J25: 49227 | K25: Hoja 1_Files_/G023.PERMESSO DI SOGGIORNO.131858.pdf | L25: 46031 | M25: Hoja 1_Files_/G023.PATENTE.131853.pdf | N25: 48325 | O25: Hoja 1_Files_/G023.TRADUZIONE PATENTE.131858.pdf | P25: 46070 | Q25: Hoja 1_Files_/G023.C. FISCALE.131853.pdf | R25: 45713 | S25: Hoja 1_Files_/ELIZANGELA.CONTRATO.105641.pdf | U25: 3478500365 | V25: elizangelasantillan@gmail.com | W25: Via Dante Alighieri, 52, 20821 Meda MB, Italia | X25: DHL | Y25: gamonaltrasporti.spedizione@gmail.com | Z25: G023 | AD25: Hoja 1_Files_/G023.RESPONSIVA.075925.pdf
A26: JULIO DIOSES | B26: AUTISTA | C26: ACTIVO | D26: PERU | E26: 29344 | F26: Hoja 1_Images/G024.IMAGEN.193337.png | I26: Hoja 1_Files_/JULIO DIOSES.CARTA DI IDENTITA.111106.pdf | K26: Hoja 1_Images/G024.PERMESSO DI SOGGIORNO.155515.jpg | M26: Hoja 1_Images/G024.PATENTE.155236.jpg | N26: 47301 | O26: Hoja 1_Images/G024.TRADUZIONE PATENTE.155515.jpg | P26: 46265 | Q26: Hoja 1_Files_/JULIO DIOSES.C. FISCALE.111108.pdf | S26: Hoja 1_Files_/G024.CONTRATO.044721.pdf | U26: 3338398834 | V26: jdioses79@gmail.com | W26: Via Pietro Metastasio, 1, 20900 Monza MB, Italia | X26: UNIVEX | Y26: marvin28abril@gmail.com | Z26: G024 | AA26: Hoja 1_Files_/G024.PERMISO UNIVEX.164359.pdf
A27: JUAN CARLOS LAZARO | B27: AUTISTA | C27: ACTIVO | D27: PERU | E27: 28737 | F27: Hoja 1_Images/G025.IMAGEN.164932.png | I27: Hoja 1_Files_/JUAN CARLOS.CARTA DI IDENTITA.182326.pdf | K27: Hoja 1_Files_/G025.PERMESSO DI SOGGIORNO.081821.pdf | L27: 45995 | M27: Hoja 1_Files_/JUAN CARLOS.PATENTE.182326.pdf | S27: Hoja 1_Files_/JUAN CARLOS.CONTRATO.195001.pdf | U27: 3208078297 | V27: Juancarloslazarolozano4@gmail.com | W27: Via S. Rocco, 118, 20831 Seregno MB, Italia | X27: DHL | Y27: gamonaltrasporti.spedizione@gmail.com | Z27: G025 | AD27: Hoja 1_Files_/G025.RESPONSIVA.073958.pdf
A28: CHRISTIAN RODRIGUEZ | B28: AUTISTA | C28: ACTIVO | D28: PERU | E28: 45703 | F28: Hoja 1_Images/G026.IMAGEN.164914.png | G28: Hoja 1_Files_/G026.PASSAPORTO.140409.pdf | H28: 46203 | J28: 36892 | K28: Hoja 1_Files_/G026.PERMESSO DI SOGGIORNO.140409.pdf | L28: 47633 | M28: Hoja 1_Files_/CHRISTIAN RODRIGUEZ.PATENTE.110931.pdf | N28: 49014 | O28: Hoja 1_Files_/G026.TRADUZIONE PATENTE.140412.pdf | P28: 46155 | Q28: Hoja 1_Files_/G026.C. FISCALE.140409.pdf | R28: 47633 | S28: Hoja 1_Files_/CHRISTIAN RODRIGUEZ.CONTRATO.194939.pdf | U28: 3514929817 | V28: Christianrodriguezmarcos@gmail.com | W28: Via Eugenio Curiel, 24, 20094 Corsico MI, Italia | X28: DHL | Y28: gamonaltrasporti.spedizione@gmail.com | Z28: G026 | AD28: Hoja 1_Files_/G026.RESPONSIVA.074917.pdf
A29: ORLANDO SICCHA | B29: AUTISTA | C29: ACTIVO | D29: PERÚ | E29: 28844 | F29: Hoja 1_Images/G027.IMAGEN.164110.png | I29: Hoja 1_Files_/ORLANDO SICCHA.CARTA DI IDENTITA.172738.pdf | M29: Hoja 1_Files_/ORLANDO SICCHA.PATENTE.172738.pdf | Q29: Hoja 1_Files_/ORLANDO SICCHA.C. FISCALE.172740.pdf | S29: Hoja 1_Files_/ORLANDO SICCHA.CONTRATO.173043.pdf | U29: 3445124845 | V29: orlandosiccha50@gmail.com | X29: UNIVEX | Y29: marvin28abril@gmail.com | Z29: G027
A30: JEAN ALVARADO | B30: AUTISTA | C30: ACTIVO | D30: PERÚ | E30: 33449 | F30: Hoja 1_Images/G028.IMAGEN.164321.png | I30: Hoja 1_Files_/JEAN ALVARADO.CARTA DI IDENTITA.173003.pdf | J30: 48425 | M30: Hoja 1_Files_/JEAN ALVARADO.PATENTE.173003.pdf | N30: 49520 | Q30: Hoja 1_Files_/G028.C. FISCALE.132350.pdf | R30: 48058 | S30: Hoja 1_Files_/G028.CONTRATO.140549.pdf | U30: +39 342 148 1557 | V30: Jeanpier1108@gmail.com | W30: Via Lorenzo Perosi, 1/5 26010 Vaiano Cremasco CR, Italia | X30: DHL | Y30: gamonaltrasporti.spedizione@gmail.com | Z30: G028 | AD30: Hoja 1_Files_/G028.RESPONSIVA.075241.pdf
A31: GAMONAL TRASPORTI | B31: EMPRESA | C31: ACTIVO | D31: PERUITALIANO | E31: 45178 | F31: Hoja 1_Images/451ba90f.IMAGEN.230508.png | V31: info@gamonaltrasporti.com | Z31: 451ba90f
A32: JHON JULIAN | B32: AUTISTA | C32: ACTIVO | D32: PERU | E32: 35416 | F32: Hoja 1_Images/G029.IMAGEN.164134.png | I32: Hoja 1_Files_/G029.CARTA DI IDENTITA.204016.pdf | M32: Hoja 1_Files_/G029.PATENTE.060124.pdf | Q32: Hoja 1_Files_/G029.C. FISCALE.211542.pdf | S32: Hoja 1_Files_/G029.CONTRATO.084557.pdf | U32: 393508243731 | V32: juliandiazjohncristian@gmail.com | X32: UNIVEX | Y32: marvin28abril@gmail.com | Z32: G029
A33: MARINO ORTEGA | B33: AUTISTA | C33: INACTIVO | D33: PERÚ | E33: 24185 | F33: Hoja 1_Images/G030.IMAGEN.230820.png | I33: Hoja 1_Files_/G030.CARTA DI IDENTITA.164133.pdf | M33: Hoja 1_Files_/G030.PATENTE.164133.pdf | X33: INACTIVO | Z33: G030
A34: FELIPE BUSTAMANTE | B34: AUTISTA | C34: ACTIVO | D34: PERÚ | E34: 34963 | F34: Hoja 1_Images/G031.IMAGEN.193358.png | I34: Hoja 1_Files_/G031.CARTA DI IDENTITA.170429.pdf | M34: Hoja 1_Files_/G031.PATENTE.170429.pdf | Q34: Hoja 1_Files_/G031.C. FISCALE.062345.59.pdf | S34: Hoja 1_Files_/G031.CONTRATO.084538.pdf | U34: 3313303702 | V34: Luisfelipe_13_ba@hotmail.com | X34: UNIVEX | Y34: marvin28abril@gmail.com | Z34: G031
A35: ADRIAN ROJAS | B35: AUTISTA | C35: ACTIVO | D35: PERÚ | E35: 36970 | F35: Hoja 1_Images/G032.IMAGEN.173415.png | I35: Hoja 1_Files_/G032.CARTA DI IDENTITA.170759.pdf | M35: Hoja 1_Files_/G032.PATENTE.170759.pdf | Q35: Hoja 1_Files_/G032.C. FISCALE.213230.pdf | S35: Hoja 1_Files_/G032.CONTRATO.083853.pdf | U35: 3508197345 | V35: Rojasuyenoadrianricardo@gmail.con | X35: UNIVEX | Y35: marvin28abril@gmail.com | Z35: G032
A36: JONATHAN CECLEN | B36: AUTISTA | C36: ACTIVO | D36: PERU | E36: 35322 | F36: Hoja 1_Images/G033.IMAGEN.164900.png | I36: Hoja 1_Files_/G033.CARTA DI IDENTITA.133801.pdf | J36: 49201 | K36: Hoja 1_Files_/G033.PERMESSO DI SOGGIORNO.133801.pdf | L36: 46417 | M36: Hoja 1_Files_/G033.PATENTE.133801.pdf | N36: 46665 | O36: Hoja 1_Files_/G033.TRADUZIONE PATENTE.133805.pdf | P36: 46062 | U36: 351 390 9109 | V36: ceclenjonathan@gmail.com | W36: Via Giacomo Matteotti 5 / Cavenago | X36: DHL | Y36: gamonaltrasporti.spedizione@gmail.com | Z36: G033
A37: ANGELO VILLAREAL | B37: AUTISTA | C37: ACTIVO | D37: Italia | E37: 39018 | F37: Hoja 1_Images/G034.IMAGEN.164846.png | I37: Hoja 1_Files_/G034.CARTA DI IDENTITA.143810.pdf | J37: 49245 | M37: Hoja 1_Files_/a52f739b.PATENTE.185029.pdf | N37: 49381 | O37: Hoja 1_Files_/G034.TRADUZIONE PATENTE.143810.pdf | P37: 46164 | Q37: Hoja 1_Files_/G034.C. FISCALE.143810.pdf | R37: 47664 | U37: 3929916431 | V37: villarrealrenzo2006@gmail.com | W37: Via Perosi 1/5 | X37: DHL | Y37: gamonaltrasporti.spedizione@gmail.com | Z37: G034 | AD37: Hoja 1_Files_/G034.RESPONSIVA.080211.pdf
A38: JEAN ARTEAGA | B38: AUTISTA | C38: ACTIVO | D38: PERU | E38: 45859 | F38: Hoja 1_Images/G035.IMAGEN.164056.png | I38: Hoja 1_Files_/G035.CARTA DI IDENTITA.171251.pdf | M38: Hoja 1_Files_/G035.PATENTE.171251.pdf | S38: Hoja 1_Files_/G035.CONTRATO.084617.pdf | U38: +39 351 435 0017 | V38: chilpa61@gmail.com | W38: Via S. Gregorio, 17, 20862 Arcore MB, Italia | X38: UNIVEX | Y38: marvin28abril@gmail.com | Z38: G035
A39: MAURO AGOSTINELLLI | B39: AUTISTA | C39: ACTIVO | D39: PERÚ | E39: 37665 | F39: Hoja 1_Images/G036.IMAGEN.025714.png | G39: Hoja 1_Files_/G036.PASSAPORTO.162257.pdf | H39: 49514 | M39: Hoja 1_Files_/G036.PATENTE.025714.pdf | N39: 49438 | U39: ‪352 030 8537‬ | V39: maufabagosgam@gmail.com | X39: UNIVEX | Y39: marvin28abril@gmail.com | Z39: G036
A40: DENNIS INGLES | B40: AUTISTA | C40: INACTIVO | D40: EL SALVADOR | E40: 33168 | F40: Hoja 1_Images/G037.IMAGEN.183932.png | I40: Hoja 1_Files_/G037.CARTA DI IDENTITA.183932.pdf | M40: Hoja 1_Files_/G037.PATENTE.183932.pdf | S40: Hoja 1_Files_/G037.CONTRATO.084024.pdf | U40: 351 839 7343 | V40: Inglesdennis8@gmail.com | W40: Via Aldo Villa, 16, 20091 Bresso MI, Italia | X40: INACTIVO | Y40: marvin28abril@gmail.com | Z40: G037
A41: DIANA SEGUIL | B41: AUTISTA | C41: ACTIVO | D41: PERÚ | E41: 35213 | F41: Hoja 1_Images/G038.IMAGEN.172927.png | M41: Hoja 1_Files_/G038.PATENTE.172927.pdf | N41: 46901 | U41: +39 345 126 2989 | V41: dianaseguil7@gmail.com | X41: DHL | Y41: gamonaltrasporti.spedizione@gmail.com | Z41: G038
...

Sheet Hoja 2
A2: TARGA | B2: MODELO | C2: IMAGEN | D2: LIBRETO | E2: ASEGURAZIONE | F2: COIBENTAZIONE | G2: AÑO | H2: TIPO | I2: ESTADO | J2: ASEGURAZIONE | K2: R.TECNICA | L2: DEROGHE | M2: ID_FURGON
A3: ER643VY | B3: FIAT DOBLO | C3: Hoja 2_Images/F001.IMAGEN.195729.png | D3: Hoja 2_Files_/ER643VY.LIBRETO.023611.pdf | E3: Hoja 2_Files_/ER643VY.ASEGURAZIONE.145308.pdf | G3: 2012 | H3: DHL | I3: DISPONIBLE | J3: 46113 | K3: 46112 | L3: 46053 | M3: F001
A4: EG403NT | B4: FORD TRANSIT | C4: Hoja 2_Images/F002.IMAGEN.193507.png | D4: Hoja 2_Files_/EG403NT.LIBRETO.025232.pdf | E4: Hoja 2_Files_/EG403NT.ASEGURAZIONE.161716.pdf | G4: 2012 | H4: DHL | I4: DISPONIBLE | J4: 46099 | K4: 45930 | L4: 46295 | M4: F002
A5: FY592SE | B5: RENAULT TRAFFIC | C5: Hoja 2_Images/F004.IMAGEN.195807.png | D5: Hoja 2_Files_/FY592SE.LIBRETO.030033.pdf | E5: Hoja 2_Files_/F004.ASEGURAZIONE.124201.pdf | F5: Hoja 2_Files_/FY592SE.COIBENTAZIONE.030035.pdf | G5: 2016 | H5: FARMACIA | I5: DISPONIBLE | J5: 46076 | K5: 46752 | L5: 46022 | M5: F004
A6: FM153VE | B6: FORD TRANSIT | C6: Hoja 2_Images/F005.IMAGEN.195820.png | D6: Hoja 2_Files_/FM153VE.LIBRETO.032648.pdf | E6: Hoja 2_Files_/FM153VE.ASEGURAZIONE.032648.pdf | F6: Hoja 2_Files_/FM153VE.COIBENTAZIONE.032650.pdf | G6: 2016 | H6: FARMACIA | I6: DISPONIBLE | J6: 46038 | K6: 46022 | L6: 46295 | M6: F005
A7: EM504JT | B7: RENAULT TRAFFIC | C7: Hoja 2_Images/F006.IMAGEN.195827.png | D7: Hoja 2_Files_/EM504JT.LIBRETO.033343. Libreto EM504JT.pdf | E7: Hoja 2_Files_/F006.ASEGURAZIONE.132335.pdf | F7: Hoja 2_Files_/EM504JT.COIBENTAZIONE.033345. Coibentazione EM504JT.pdf | G7: 2012 | H7: FARMACIA | I7: DISPONIBLE | J7: 46129 | K7: 46446 | M7: F006
A8: FY032BD | B8: RENAULT TRAFFIC | C8: Hoja 2_Images/F007.IMAGEN.195848.png | D8: Hoja 2_Files_/FY032BD.LIBRETO.033605. Libreto FY302BD.pdf | E8: Hoja 2_Files_/F007.ASEGURAZIONE.132928.pdf | F8: Hoja 2_Files_/FY032BD.COIBENTAZIONE.033607. Coibentazione FY302BD.pdf | G8: 2019 | H8: FARMACIA | I8: DISPONIBLE | J8: 46153 | K8: 46629 | L8: 46295 | M8: F007
A9: GE027AM | B9: RENAULT TRAFFIC | C9: Hoja 2_Images/F008.IMAGEN.195857.png | D9: Hoja 2_Files_/GE027AM.LIBRETO.033744. Libreto GE027AM.pdf | E9: Hoja 2_Files_/F008.ASEGURAZIONE.133629.pdf | F9: Hoja 2_Files_/GE027AM.COIBENTAZIONE.033746. Coibentazione GE027AM.pdf | G9: 2021 | H9: FARMACIA | I9: DISPONIBLE | J9: 46157 | K9: 46477 | M9: F008
A10: FN505ZH | B10: MERCEDES VITO | C10: Hoja 2_Images/F009.IMAGEN.195912.png | D10: Hoja 2_Files_/FN505ZH.LIBRETO.034022. Libreto FN505ZH.pdf | E10: Hoja 2_Files_/F009.ASEGURAZIONE.133359.pdf | F10: Hoja 2_Files_/FN505ZH.COIBENTAZIONE.034024. Coibentazione FN505ZH.pdf | G10: 2021 | H10: FARMACIA | I10: DISPONIBLE | J10: 46154 | K10: 46173 | L10: 46295 | M10: F009
A11: EX030XG | B11: Audi A3 | C11: Hoja 2_Images/F010.IMAGEN.193255.png | D11: Hoja 2_Files_/EX030XG.LIBRETO.170552.pdf | E11: Hoja 2_Files_/F010.ASEGURAZIONE.103420.pdf | G11: 2014 | H11: DHL | I11: DISPONIBLE | J11: 46021 | K11: 46446 | M11: F010
A12: GT894FF | B12: Ford Puma | C12: Hoja 2_Images/F011.IMAGEN.193456.png | D12: Hoja 2_Files_/GT894FF.LIBRETO.153351.pdf | E12: Hoja 2_Files_/F011.ASEGURAZIONE.100005.pdf | G12: 2024 | H12: DHL | I12: DISPONIBLE | J12: 45952 | K12: 46843 | M12: F011
A13: DZ923BS | B13: Hyundai Santa Fe | C13: Hoja 2_Images/F012.IMAGEN.193442.png | D13: Hoja 2_Files_/DZ923BS.LIBRETO.223150.pdf | E13: Hoja 2_Files_/F012.ASEGURAZIONE.165350.pdf | G13: 2009 | H13: DHL | I13: DISPONIBLE | J13: 46046 | K13: 46081 | M13: F012
A14: CV627GV | B14: Mercedes Benz | C14: Hoja 2_Images/F013.IMAGEN.194425.png | D14: Hoja 2_Files_/CV627GV.LIBRETO.222721.pdf | E14: Hoja 2_Files_/CV627GV.ASEGURAZIONE.050430.pdf | G14: 2003 | H14: DHL | I14: DISPONIBLE | J14: 46018 | K14: 46446 | M14: F013
A15: GB502TP | B15: Fiat Panda | C15: Hoja 2_Images/F014.IMAGEN.194447.png | D15: Hoja 2_Files_/GB502TP.LIBRETO.153118.pdf | E15: Hoja 2_Files_/F014.ASEGURAZIONE.105412.pdf | G15: 2021 | H15: DHL | I15: DISPONIBLE | J15: 46021 | K15: 46234 | M15: F014
A16: ET420XR | B16: Alfa Romeo | C16: Hoja 2_Images/ET420XR.IMAGEN.193634.jpg | D16: Hoja 2_Files_/ET420XR.LIBRETO.224609.pdf | E16: Hoja 2_Files_/ET420XR.ASEGURAZIONE.205224.pdf | G16: 2014 | H16: VENDIDO | I16: NO DISPONIBLE | J16: 45853 | K16: 45868 | M16: F015
A17: FY593SE | B17: RENAULT TRAFFIC | C17: Hoja 2_Images/F016.IMAGEN.195920.png | D17: Hoja 2_Files_/FY953SE.LIBRETO.170323.pdf | E17: Hoja 2_Files_/F016.ASEGURAZIONE.160842.pdf | F17: Hoja 2_Files_/FY593SE.COIBENTAZIONE.092433.pdf | G17: 2018 | H17: FARMACIA | I17: DISPONIBLE | J17: 46050 | K17: 46022 | M17: F016
A18: GD079DK | B18: RENAULT TRAFFIC | C18: Hoja 2_Images/F017.IMAGEN.195931.png | D18: Hoja 2_Files_/GD079DK.LIBRETO.135149.pdf | E18: Hoja 2_Files_/F017.ASEGURAZIONE.171037.pdf | F18: Hoja 2_Files_/GD079DK.COIBENTAZIONE.173118.pdf | G18: 2020 | H18: FARMACIA | I18: DISPONIBLE | J18: 46060 | K18: 46387 | M18: F017
A19: GP390DZ | B19: FIAT DUCATO | C19: Hoja 2_Images/F018.IMAGEN.195944.png | D19: Hoja 2_Files_/GP390DZ.LIBRETO.052243.pdf | E19: Hoja 2_Files_/F018.ASEGURAZIONE.105535.pdf | G19: 2023 | H19: FARMACIA | I19: DISPONIBLE | J19: 45988 | M19: F018
A20: GP392DZ | B20: FIAT DUCATO | C20: Hoja 2_Images/F019.IMAGEN.195953.png | D20: Hoja 2_Files_/GP392DZ.LIBRETO.052322.pdf | E20: Hoja 2_Files_/F019.ASEGURAZIONE.105801.pdf | G20: 2023 | H20: FARMACIA | I20: DISPONIBLE | J20: 45988 | M20: F019
A21: GM089XH | B21: FIAT DUCATO | C21: Hoja 2_Images/F020.IMAGEN.200007.png | D21: Hoja 2_Files_/GM089XH.LIBRETO.052528.pdf | E21: Hoja 2_Files_/F020.ASEGURAZIONE.110014.pdf | G21: 2023 | H21: FARMACIA | I21: DISPONIBLE | J21: 45988 | L21: 46053 | M21: F020
A22: CT413YE | B22: Polo | C22: Hoja 2_Images/F021.IMAGEN.194501.png | D22: Hoja 2_Files_/CT413YE.LIBRETO.152918.pdf | E22: Hoja 2_Files_/CT413YE.ASEGURAZIONE.144851.pdf | G22: 2005 | H22: DHL | I22: DISPONIBLE | J22: 46108 | K22: 46507 | M22: F021
A23: EZ009PN | B23: KANGOO | C23: Hoja 2_Images/F022.IMAGEN.194517.png | D23: Hoja 2_Files_/EZ009PN.LIBRETO.120555.pdf | E23: Hoja 2_Files_/EZ009PN.ASEGURAZIONE.124003.pdf | G23: 2015 | H23: DHL | I23: DISPONIBLE | J23: 46106 | K23: 46599 | M23: F022
A24: GJ980KT | B24: LAMBERET BOXER | C24: Hoja 2_Images/F023.IMAGEN.200030.png | D24: Hoja 2_Files_/GJ980KT.LIBRETO.164706.pdf | G24: 2022 | H24: FARMACIA | I24: NO DISPONIBLE | M24: F023
A25: EL49520 | B25: YAMAHA MT-125 | C25: Hoja 2_Images/F024.IMAGEN.194527.png | D25: Hoja 2_Files_/EL49520.LIBRETO.162527.pdf | E25: Hoja 2_Files_/EL49520.ASEGURAZIONE.163944.pdf | G25: 2018 | H25: DHL | I25: DISPONIBLE | J25: 46107 | K25: 46295 | M25: F024
A26: FM342HY | B26: FORD TRANSIT | C26: Hoja 2_Images/F025.IMAGEN.194542.png | D26: Hoja 2_Files_/FM342HY.LIBRETO.124008.pdf | E26: Hoja 2_Files_/FM342HY.ASEGURAZIONE.124008.pdf | G26: 2017 | H26: DHL | I26: DISPONIBLE | J26: 46125 | K26: 46721 | L26: 46295 | M26: F025
A27: ES638NF | B27: FIAT FIORINO | C27: Hoja 2_Images/F026.IMAGEN.194603.png | D27: Hoja 2_Files_/ES638NF.LIBRETO.154251.pdf | E27: Hoja 2_Files_/ES638NF.ASEGURAZIONE.154251.PDF | G27: 2014 | H27: DHL | I27: DISPONIBLE | J27: 46140 | K27: 46053 | M27: F026
A28: GZ992SA | B28: Peugeot | C28: Hoja 2_Images/F027.IMAGEN.181435.png | D28: Hoja 2_Images/F027.LIBRETO.111309.jpg | E28: Hoja 2_Files_/F027.ASEGURAZIONE.110324. GZ992SA.pdf | G28: 2025 | H28: FARMACIA | I28: DISPONIBLE | J28: 46218 | K28: 45875 | M28: F027
A29: FG133WJ | B29: FIAT FIORINO | C29: Hoja 2_Images/F028.IMAGEN.162709.png | D29: Hoja 2_Images/F028.LIBRETO.162709.jpg | E29: Hoja 2_Files_/F028.ASEGURAZIONE.162709.PDF | G29: 2016 | H29: DHL | I29: DISPONIBLE | J29: 46060 | M29: F028
A30: GJ919FZ | B30: CASONATO | C30: Hoja 2_Images/F029.IMAGEN.065135.png | H30: DHL | I30: NO DISPONIBLE | M30: F029
A31: ES270BA | B31: RENAULT TRAFFIC | C31: Hoja 2_Images/F003.IMAGEN.183135.png | D31: Hoja 2_Files_/F003.LIBRETO.134448.52.pdf | G31: 2019 | H31: FARMACIA | I31: DISPONIBLE | J31: 45931 | K31: 46659 | M31: F003
A32: DH950ZM | B32: NOLEGGIO UNIVEX | C32: Hoja 2_Images/999999.IMAGEN.194119.png | H32: FARMACIA | I32: DISPONIBLE | M32: F099
A33: GZ719WV | B33: Vehículo Piazza | C33: Hoja 2_Images/12345.IMAGEN.000123.png | H33: DHL | I33: DISPONIBLE | M33: F097
A34: NOLEGGIO/OTRO | B34: NOLEGGIO/OTRO | C34: Hoja 2_Images/G100.IMAGEN.195101.png | H34: FARMACIA | I34: DISPONIBLE | M34: G100
A35: FG346WJ | B35: FIAT DUCATO | C35: Hoja 2_Images/F030.IMAGEN.163854.png | H35: DHL | I35: DISPONIBLE | J35: 46186 | M35: F030
A36: GS042KA | B36: NOLEGGIO UNIVEX | C36: Hoja 2_Images/F098.IMAGEN.160059.jpg | H36: FARMACIA | I36: DISPONIBLE | M36: F098

Sheet TABLA IDS
A1: Correo | B1: ID TRABAJADOR | C1: Nombre
A2: autista.gamonaltrasporti@gmail.com | B2: G003 | C2: YAN GAMONAL
A3: elizangelasantillan@gmail.com | B3: G023 | C3: ELIZANGELA CHUMBE
A4: Christianrodriguezmarcos@gmail.com | B4: G026 | C4: CHRISTIAN RODRIGUEZ
A5: ceclenjonathan@gmail.com | B5: G033 | C5: JONATHAN CECLEN
A6: Jeanpier1108@gmail.com | B6: G028 | C6: JEAN ALVARADO
A7: jurgen2000pv@gmail.com | B7: G017 | C7: JURGEN PALIZA
A8: Juancarloslazarolozano4@gmail.com | B8: G025 | C8: JUAN LAZARO
A9: 14jatg07@gmail.com | B9: G014 | C9: ALONSO TAMARA
A10: villarrealrenzo2006@gmail.com | B10: G034 | C10: ANGELO VILLAREAL
A11: quispehinostrozaromario1995@gmail.com | B11: G011 | C11: ROMARIO QUISPE
A12: marvin28abril@gmail.com | B12: G008 | C12: MARVIN CASTILLO
... A31: aliaga1303@gmail.com | B31: G042 | C31: JOHANN ALIAGA

Sheet GIROS FARMACIA
A1: NOMBRE | B1: ID TRABAJADOR | C1: MATTINA | D1: INTERMEDIO | E1: POMERIGGIO
A2: ROMARIO | B2: G011 | C2: 101 - SETTIMO MILANESE | E2: 301 - PARABIAGO
A3: CESAR | B3: G007 | C3: 102 - ARESE | E3: 302 - MAGENTA
A4: ADRIAN | B4: G032 | C4: 103 - GUISSANO | E4: 363 - SEREGNO
A5: JUAN | B5: G016 | C5: 114 - MALPIGHI | D5: 210 - MILANO | E5: 314 - MILANO
A6: ANTONIO | B6: G021 | C6: 115 - NOVA MILANESE | E6: 315 - LIMBIATE
A7: FELIPE | B7: G031 | C7: 117 - SESTO | E7: 317 - SESTO
A8: DIEGO | B8: G020 | C8: 119 - VIMERCATE | D8: 228 - MOZZATE | E8: 319 - COMO
A9: JAIRO | B9: G041 | C9: 120 - BRUGHERIO | D9: NAVETTA LALLIO | E9: 311 - MILANO
A10: JULIO | B10: G024 | C10: 123 - MERATE | D10: 211 - SEREGNO | E10: 323 - VIMERCATE
A11: ANGEL | B11: G040 | C11: 128 - MOZZATE | E11: 328 - MOZZATE
A12: JEAN PIER | B12: G035 | C12: 162 - LECCO | D12: 201 - BELLUSCO | E12: 320 - BRUGHERIO
A13: DENNIS | B13: G037 | C13: 198 - MILANO BOOTS | E13: 398- BOOTS
A14: JHON | B14: G029 | C14: 199 - DUOMO | E14: 399 - DUOMO
A15: ORLANDO | B15: G027 | C15: 570 - BERGAMO | E15: 362 - BLUESERVICE

Sheet MECANICA
A2: TARGA | B2: ID_FURGON | C2: MODELO | D2: ESTADO | E2: NOME | F2: DATA | G2: KM | H2: DOCUMENTOS | I2: GPS | J2: CLACSON | K2: RADIO | L2: ANTENA | M2: ACCESORIOS CEL | N2: SPECHIETTO DIESTRO | O2: SPECHIETTO SINIESTRO | P2: TAPPETTINI | Q2: MANIGLIE | R2: ACQUA PER VETRO | S2: TERGICRISTALLI | T2: LUCI DAVANTI | U2: LUCI POSTERIORI | V2: KIT DE SEGURIDAD | W2: ESTADO DE LLANTAS | X2: LLANTA DE REPUESTO | Y2: VETRO ANTERIORE | Z2: FRIGO | AA2: ARIA CONDIZIONATA | AB2: FOTO 1 | AC2: FOTO 2 | AD2: FOTO 3 | AE2: FOTO 4 | AF2: FIRMA | AG2: COMENTARIO | AH2: TIPO | AI2: IMAGEN
A3: ER643VY | B3: F001 | C3: FIAT DOBLO | D3: OPTIMO | E3: ORLANDO SICCHA | F3: 45986 | G3: 481633 | H3: SI | I3: NO | J3: NO | K3: SI | L3: NO | M3: SI | N3: SI | O3: SI | P3: SI | Q3: SI | R3: SI | S3: SI | T3: SI | U3: SI | V3: SI | W3: SI | X3: SI | Y3: NO | Z3: SI | AA3: SI | AF3: MECANICA_Images/ER643VY.FIRMA.090658.png | AG3: Por controlar : mangera de agua .siatema electrico de gas | AH3: FURGONE | AI3: Hoja 2_Images/ER643VY.IMAGEN.023611.jpg
A4: EG403NT | B4: F002 | C4: FORD TRANSIT | D4: NO OPTIMO | E4: ROMARIO QUISPE | F4: 45897 | G4: 244216 | H4: SI | I4: NO | J4: SI | K4: NO | L4: NO | M4: NO | N4: SI | O4: SI | P4: SI | Q4: SI | R4: SI | S4: SI | T4: SI | U4: SI | V4: SI | W4: NO | X4: NO | Y4: NO | Z4: SI | AA4: NO | AF4: MECANICA_Images/EG403NT.FIRMA.150225.png | AG4: falta revisar falla electronica no tiene llanta de repuesto por motivo de glp cambio de bolano y marcia | AH4: FURGONE | AI4: Hoja 2_Images/EG403NT.IMAGEN.025232.png
A5: ES270BA | B5: F003 | C5: RENAULT MASTER | D5: OPTIMO | F5: 45813 | AB5: MECANICA_Images/ES270BA.FOTO 1.110158.jpg | AD5: MECANICA_Images/ES270BA.FOTO 3.110157.jpg | AG5: CINTURÓN DE SEGURIDAD | AH5: FURGONE | AI5: Hoja 2_Images/ES270BA.IMAGEN.025613.png
A6: FY592SE | B6: F004 | C6: RENAULT TRAFFIC T27 | D6: CON FALLAS | E6: EDWAR GUERRERO | F6: 45897 | H6: SI | I6: SI | J6: SI | K6: SI | L6: NO | M6: NO | N6: SI | O6: SI | P6: SI | Q6: SI | R6: NO | S6: SI | T6: SI | U6: SI | V6: SI | W6: SEMINUEVAS | X6: SI | Y6: NO | Z6: SI | AA6: SI | AB6: MECANICA_Images/FY592SE.FOTO 1.074245.jpg | AC6: MECANICA_Images/FY592SE.FOTO 2.074245.jpg | AD6: MECANICA_Images/FY592SE.FOTO 3.074244.jpg | AE6: MECANICA_Images/FY592SE.FOTO 4.074247.jpg | AG6: falta alineamiento, persiste spia antiderrape | AH6: FURGONE | AI6: Hoja 2_Images/FY592SE.IMAGEN.030033.png
A7: FM153VE | B7: F005 | C7: FORD TRANSIT | D7: OPTIMO | E7: ALONSO TAMARA | F7: 45817 | H7: SI | I7: SI | J7: SI | K7: SI | M7: SI | N7: SI | O7: SI | P7: SI | Q7: SI | R7: NO | S7: SI | T7: SI | U7: SI | V7: SI | W7: SEMINUEVAS | X7: SI | Z7: SI | AA7: SI | AH7: FURGONE | AI7: Hoja 2_Images/FM153VE.IMAGEN.032648.png
A8: EM504JT | B8: F006 | C8: RENAULT TRAFFIC | D8: CON FALLAS | E8: DIEGO MOLINA | F8: 45897 | H8: SI | I8: SI | J8: SI | K8: SI | M8: SI | N8: SI | O8: SI | P8: SI | Q8: SI | R8: NO | S8: SI | T8: SI | U8: SI | V8: NO | W8: SEMINUEVAS | X8: SI | Y8: NO | Z8: SI | AA8: SI | AB8: MECANICA_Images/EM504JT.FOTO 1.110503.jpg | AG8: ,Revisar dirección, por el techo está filtrando agua | AH8: FURGONE | AI8: Hoja 2_Images/EM504JT.IMAGEN.033343.png
A9: FY032BD | B9: F007 | C9: RENAULT TRAFFIC | D9: NO OPTIMO | E9: JURGEN PALIZA | F9: 45942 | H9: SI | I9: SI | J9: SI | K9: SI | M9: SI | N9: SI | O9: SI | P9: SI | Q9: SI | R9: SI | S9: SI | T9: SI | U9: SI | V9: SI | W9: SEMINUEVAS | X9: SI | Y9: NO | Z9: SI | AA9: SI | AB9: MECANICA_Images/FY032BD.FOTO 1.105924.jpg | AC9: MECANICA_Images/FY032BD.FOTO 2.105924.jpg | AG9: Esta perdiendo liquido radiatore Fallas Per consumo de olio. | AH9: FURGONE | AI9: Hoja 2_Images/FY032BD.IMAGEN.033605.png
A10: GE027AM | B10: F008 | C10: RENAULT TRAFFIC | D10: OPTIMO | E10: ORLANDO SICCHA | F10: 45817 | G10: 270604 | H10: SI | I10: SI | J10: SI | K10: SI | L10: SI | M10: SI | N10: SI | O10: SI | P10: SI | Q10: SI | R10: SI | S10: SI | T10: SI | U10: SI | V10: SI | W10: SI | X10: SI | Y10: SI | Z10: SI | AA10: SI | AF10: MECANICA_Images/GE027AM.FIRMA.082524.png | AG10: Puerta del copiloto no cierra. | AH10: FURGONE | AI10: Hoja 2_Images/GE027AM.IMAGEN.033744.png
A11: FN505ZH | B11: F009 | C11: MERCEDES VITO | D11: OPTIMO | E11: ANTONIO RIVERA | F11: 45897 | H11: SI | I11: SI | J11: SI | K11: NO | M11: SI | N11: SI | O11: SI | P11: SI | Q11: SI | R11: NO | S11: SI | T11: SI | U11: SI | V11: SI | W11: SEMINUEVAS | X11: SI | Y11: NO | Z11: SI | AA11: SI | AH11: FURGONE | AI11: Hoja 2_Images/FN505ZH.IMAGEN.034022.png
A12: EX030XG | B12: F010 | C12: AUDI A3 | D12: OPTIMO | E12: LIBRE | F12: 45756 | G12: 0 | W12: NA | X12: SI | AB12: MECANICA_Images/EX030XG.FOTO 1.215401.jpg | AF12: MECANICA_Images/EX030XG.FIRMA.062556.png | AG12: Prueba | AH12: AUTO | AI12: Hoja 2_Images/EX030XG.IMAGEN.034226.jpg
A13: GT894FF | B13: F011 | C13: FORD PUMA | D13: SIN REVISAR | AH13: AUTO | AI13: Hoja 2_Images/GT894FF.IMAGEN.034303.jpg
A14: DZ923BS | B14: F012 | C14: SANTA FE | D14: OPTIMO | E14: ROMARIO QUISPE | F14: 45757 | H14: SI | I14: NO | J14: SI | K14: SI | L14: SI | M14: SI | N14: SI | O14: SI | P14: SI | Q14: SI | R14: SI | S14: SI | T14: SI | U14: SI | V14: SI | W14: SI | X14: SI | Y14: SI | Z14: NO | AA14: NA | AF14: MECANICA_Images/DZ923BS.FIRMA.085718.png | AG14: carro en optimas condiciones | AH14: AUTO | AI14: Hoja 2_Images/DZ923BS.IMAGEN.034348.jpg
A15: CV627GV | B15: F013 | C15: MERCEDES BENZ | D15: OPTIMO | E15: MARTIN RODRIGUEZ | F15: 45814 | H15: SI | I15: SI | J15: SI | K15: SI | L15: SI | M15: SI | N15: SI | O15: SI | P15: SI | Q15: SI | R15: SI | S15: SI | T15: SI | U15: SI | V15: NO | W15: NO | X15: NA | Y15: NA | Z15: NO | AA15: SI | AF15: MECANICA_Images/CV627GV.FIRMA.080657.png | AG15: Fermo administrativo | AH15: AUTO | AI15: Hoja 2_Images/CV627GV.IMAGEN.193347.jpg
A16: GB502TP | B16: F014 | C16: FIAT PANDA | D16: OPTIMO | E16: EDUARDO SANTA CRUZ | F16: 45755 | G16: 13271 | H16: SI | I16: NO | J16: SI | K16: SI | L16: SI | M16: SI | N16: SI | O16: SI | P16: SI | Q16: SI | R16: SI | S16: SI | T16: SI | U16: SI | V16: SI | W16: NO | X16: SI | Y16: SI | Z16: NO | AA16: SI | AB16: MECANICA_Images/GB502TP.FOTO 1.075545.jpg | AC16: MECANICA_Images/GB502TP.FOTO 2.075546.jpg | AD16: MECANICA_Images/GB502TP.FOTO 3.075546.jpg | AF16: MECANICA_Images/GB502TP.FIRMA.081911.png | AG16: Por revisar la rueda de adelante lado del chofer | AH16: AUTO | AI16: Hoja 2_Images/GB502TP.IMAGEN.193401.jpg
A17: ET420XR | B17: F015 | C17: ALFA ROMEO | D17: NO OPTIMO | E17: LUIS POMA | F17: 45908 | H17: SI | I17: SI | J17: SI | K17: SI | M17: SI | N17: SI | O17: SI | P17: SI | Q17: SI | R17: SI | S17: SI | T17: SI | U17: SI | V17: SI | W17: SEMINUEVAS | X17: SI | Y17: NO | Z17: NO | AA17: NO | AH17: AUTO | AI17: Hoja 2_Images/ET420XR.IMAGEN.193634.jpg
A18: FY593SE | B18: F016 | C18: RENAULT TRAFFIC | D18: OPTIMO | E18: ELIZANGELA CHUMBE | F18: 45908 | H18: SI | I18: SI | J18: SI | M18: SI | N18: SI | O18: SI | P18: SI | Q18: SI | R18: SI | S18: SI | T18: SI | U18: SI | V18: SI | W18: SEMINUEVAS | X18: SI | Y18: NO | Z18: SI | AA18: SI | AH18: FURGONE | AI18: Hoja 2_Images/FY953SE.IMAGEN.170323.jpg
A19: GD079DK | B19: F017 | C19: RENAULT TRAFFIC | D19: CON FALLAS | E19: JEAN ALVARADO | F19: 45817 | H19: SI | I19: SI | K19: SI | M19: SI | N19: SI | O19: SI | P19: SI | Q19: SI | R19: NO | S19: SI | T19: SI | U19: SI | V19: SI | W19: SEMINUEVAS | X19: SI | Y19: NO | Z19: SI | AA19: SI | AB19: MECANICA_Images/GD079DK.FOTO 1.110825.jpg | AG19: Faro derecho roto por JEANPIER | AH19: FURGONE | AI19: Hoja 2_Images/GD079DK.IMAGEN.173116.png
A20: GP390DZ | B20: F018 | C20: FIAT DUCATO | D20: OPTIMO | E20: MARVIN CASTILLO | F20: 45758 | H20: SI | I20: SI | J20: SI | K20: SI | M20: SI | N20: SI | O20: SI | P20: SI | Q20: SI | R20: SI | S20: SI | T20: SI | U20: SI | V20: SI | Y20: SI | Z20: SI | AA20: SI | AH20: NOLEGGIO | AI20: Hoja 2_Images/GP390DZ.IMAGEN.052243.png
A21: GP392DZ | B21: F019 | C21: FIAT DUCATO | D21: OPTIMO | E21: JULIO DIOSES | F21: 45758 | H21: SI | I21: SI | J21: SI | K21: SI | M21: SI | N21: SI | O21: SI | P21: SI | Q21: SI | R21: SI | S21: SI | T21: SI | U21: SI | V21: SI | Y21: NO | Z21: SI | AA21: SI | AH21: NOLEGGIO | AI21: Hoja 2_Images/GP392DZ.IMAGEN.052322.png
A22: GM089XH | B22: F020 | C22: FIAT DUCATO | D22: OPTIMO | E22: JUAN TEJADA | F22: 45897 | H22: SI | I22: SI | J22: NO | K22: SI | M22: SI | N22: SI | O22: SI | P22: SI | Q22: SI | R22: SI | S22: SI | T22: SI | U22: SI | V22: SI | W22: PARA CAMBIO | X22: SI | Y22: NO | Z22: SI | AA22: NO | AG22: Senza aria condizionata | AH22: NOLEGGIO | AI22: Hoja 2_Images/GM089XH.IMAGEN.052528.png
A23: CT413YE | B23: F021 | C23: POLO | D23: OPTIMO | E23: ROMARIO QUISPE | F23: 45756 | G23: 177382 | H23: SI | I23: NO | J23: SI | K23: SI | L23: SI | M23: SI | N23: SI | O23: SI | P23: SI | Q23: SI | R23: SI | S23: SI | T23: SI | U23: SI | V23: SI | W23: NO | X23: SI | Y23: SI | Z23: NO | AA23: SI | AF23: MECANICA_Images/CT413YE.FIRMA.082832.png | AG23: chanca el amolrtiguador | AH23: AUTO | AI23: Hoja 2_Images/CT413YE.IMAGEN.152918.png
A24: EZ009PN | B24: F022 | C24: KANGOO | D24: OPTIMO | E24: JUAN CARLOS | F24: 45755 | G24: 231665 | H24: SI | I24: SI | J24: SI | K24: SI | L24: SI | M24: SI | N24: SI | O24: SI | P24: SI | Q24: SI | R24: SI | S24: SI | T24: SI | U24: SI | V24: NO | W24: NO | X24: SI | Y24: SI | Z24: NO | AA24: NA | AF24: MECANICA_Images/EZ009PN.FIRMA.085220.png | AG24: programardo tallando sabado 10/05 | AH24: FURGONE | AI24: Hoja 2_Images/EZ009PN.IMAGEN.154153.png
A25: GJ919FZ | C25: VOLKSWAGEN | D25: OPTIMO | AG25: Telonato
A26: EL49520 | B26: F024 | C26: YAMAHA MT-125 | D26: OPTIMO | E26: CHRISTIAN RODRIGUEZ | F26: 45910 | H26: SI | I26: NO | J26: SI | K26: NO | L26: NO | M26: NO | N26: SI | O26: SI | P26: NO | Q26: NO | R26: NO | S26: NO | T26: SI | U26: SI | W26: NO | X26: NO | Y26: NO | Z26: NO | AA26: NO | AF26: MECANICA_Images/EL49520.FIRMA.093145.png | AG26: Moto en optimas condiciones | AH26: MOTO | AI26: Hoja 2_Images/EL49520.IMAGEN.170851.png
A27: FM342HY | B27: F025 | C27: Ford transit | D27: OPTIMO | E27: ROMARIO QUISPE | F27: 45910 | G27: 208357 | H27: SI | I27: NO | J27: SI | K27: SI | L27: SI | M27: NO | N27: SI | O27: SI | P27: SI | Q27: SI | R27: SI | S27: SI | T27: SI | U27: SI | V27: NO | W27: SEMINUEVAS | X27: SI | Y27: SI | Z27: NO | AA27: SI | AB27: MECANICA_Images/FM342HY.FOTO 1.072000.jpg | AC27: MECANICA_Images/FM342HY.FOTO 2.072000.jpg | AD27: MECANICA_Images/FM342HY.FOTO 3.072000.jpg | AE27: MECANICA_Images/FM342HY.FOTO 4.072003.jpg | AF27: MECANICA_Images/FM342HY.FIRMA.072002.png | AG27: Falta aserle su mantenimiento y resivar el aire acondicionado | AH27: FURGONE | AI27: MECANICA_Images/FM342HY.IMAGEN.072058.jpg
A28: ES638NF | B28: F026 | C28: Fiad fiorino | D28: OPTIMO | E28: JUAN CARLOS | F28: 45786 | G28: 84546 | H28: SI | I28: SI | J28: SI | K28: SI | L28: SI | M28: SI | N28: SI | O28: SI | P28: SI | Q28: SI | R28: SI | S28: SI | T28: SI | U28: SI | V28: SI | W28: SEMINUEVAS | X28: SI | Y28: NO | Z28: NO | AA28: SI | AB28: MECANICA_Images/ES638NF.FOTO 1.141612.jpg | AC28: MECANICA_Images/ES638NF.FOTO 2.141612.jpg | AD28: MECANICA_Images/ES638NF.FOTO 3.141612.jpg | AF28: MECANICA_Images/ES638NF.FIRMA.141615.png | AG28: Carro óptimo | AH28: FURGONE | AI28: MECANICA_Images/ES638NF.IMAGEN.141615.jpg

Sheet RECORDATORIOS 
A1: ID | B1: TARGA | C1: SCADENZA | D1: TIPO
A2: 66f77cc6 | B2: GT894FF | C2: 45891 | D2: ASEGURACIÓN
A3: 51305a48 | B3: GT894FF | C3: 46843 | D3: REVISION TECNICA
A4: 25050f71 | B4: GE027AM | C4: 45976 | D4: ASEGURACIÓN
A5: c559c7f3 | B5: GB502TP | C5: 46021 | D5: ASEGURACIÓN
A6: 334143ea | B6: GB502TP | C6: 46234 | D6: REVISION TECNICA
A7: 57f4359b | B7: FY593SE | C7: 46050 | D7: ASEGURACIÓN
A8: d390eedd | B8: FY593SE | C8: 45991 | D8: REVISION TECNICA
A9: 445954eb | B9: FY592SE | C9: 46022 | D9: DEROGHE
A10: 09cf3807 | B10: FY592SE | C10: 45892 | D10: ASEGURACIÓN
A11: f1ceecaf | B11: FY592SE | C11: 45991 | D11: REVISION TECNICA
A12: 74d7c9b3 | B12: FY032BD | C12: 46295 | D12: DEROGHE
A13: 5d952fb3 | B13: FY032BD | C13: 45967 | D13: ASEGURACIÓN
... A52: 89d90ad2 | B52: FM342HY | C52: 46295 | D52: DEROGHE

Sheet EDENRED
A1: ID | B1: MES | C1: ÁREA | D1: NOMBRE | E1: S1 | F1: S2 | G1: S3 | H1: S4 | I1: TOTAL | J1: Id_Trabajador | K1: COMENTARIOS
A2: c5788f93 | B2: 2. FEBRERO | C2: FARMACIA | D2: MARVIN CASTILLO | E2: 25 | F2: 25 | G2: 25 | H2: 25 | I2: 100 | J2: G008 | K2: Buen mes
A3: 6fe80557 | B3: 2. FEBRERO | C3: FARMACIA | D3: JUAN TEJADA | E3: 25 | F3: 25 | G3: 25 | H3: 25 | I3: 100 | J3: G016
A4: 5d88aae9 | B4: 2. FEBRERO | C4: FARMACIA | D4: JURGEN PALIZA | E4: 25 | F4: 25 | G4: 25 | H4: 25 | I4: 100 | J4: G017 | K4: Buen mes
A5: 4ebbd750 | B5: 2. FEBRERO | C5: INACTIVO | D5: ADOLFO ROSALES | F5: 0 | G5: 0 | H5: 0 | I5: 0 | J5: G013
A6: 5133fc87 | B6: 2. FEBRERO | C6: FARMACIA | D6: ALONSO TAMARA | E6: 15 | F6: 15 | G6: 15 | H6: 15 | I6: 60 | J6: G014
A7: 74d2a46a | B7: 2. FEBRERO | C7: FARMACIA | D7: EDWAR GUERRERO | E7: 15 | F7: 15 | G7: 15 | H7: 15 | I7: 60 | J7: G015
A8: 39464ec4 | B8: 2. FEBRERO | C8: FARMACIA | D8: CESAR PLUA | E8: 25 | F8: 25 | G8: 25 | H8: 25 | I8: 100 | J8: G007
A9: 4e6ed272 | B9: 2. FEBRERO | C9: INACTIVO | D9: ROMARIO QUISPE | E9: 25 | F9: 25 | G9: 25 | H9: 25 | I9: 100 | J9: G011
A10: d4a6843d | B10: 2. FEBRERO | C10: INACTIVO | D10: DOMINICK LEON | E10: 10 | F10: 10 | G10: 10 | I10: 30 | J10: G009
A11: 9gd8s13 | B11: 3. MARZO | C11: FARMACIA | D11: MARVIN CASTILLO | E11: 25 | F11: 15 | G11: 20 | H11: 20 | I11: 80 | J11: G008
A12: qw98r1532 | B12: 3. MARZO | C12: FARMACIA | D12: JUAN TEJADA | E12: 20 | F12: 20 | G12: 20 | H12: 15 | I12: 75 | J12: G016
A13: vb988 | B13: 3. MARZO | C13: FARMACIA | D13: JURGEN PALIZA | E13: 20 | F13: 20 | G13: 20 | H13: 20 | I13: 80 | J13: G017
A14: ku6yjm1, | B14: 3. MARZO | C14: FARMACIA | D14: ALONSO TAMARA | E14: 20 | F14: 15 | G14: 15 | H14: 20 | I14: 70 | J14: G014
A15: s98db | B15: 3. MARZO | C15: FARMACIA | D15: EDWAR GUERRERO | E15: 20 | F15: 20 | G15: 20 | H15: 15 | I15: 75 | J15: G015
A16: 9iuo8p4 | B16: 3. MARZO | C16: FARMACIA | D16: CESAR PLUA | E16: 25 | F16: 20 | G16: 20 | H16: 25 | I16: 90 | J16: G007
A17: ljk3ñ21 | B17: 3. MARZO | C17: INACTIVO | D17: ROMARIO QUISPE | E17: 20 | F17: 20 | G17: 20 | H17: 20 | I17: 80 | J17: G011
A18: 665b81nm | B18: 3. MARZO | C18: INACTIVO | D18: DOMINICK LEON | E18: 5 | F18: 10 | G18: 10 | H18: 5 | I18: 30 | J18: G009
A19: q9w87r | B19: 3. MARZO | C19: DHL | D19: JUAN CARLOS | E19: 20 | F19: 20 | G19: 20 | H19: 20 | I19: 80 | J19: G025
A20: t8ur879 | B20: 4. ABRIL | C20: FARMACIA | D20: MARVIN CASTILLO | E20: 15 | F20: 20 | G20: 20 | H20: 25 | I20: 80 | J20: G008
A21: qr98 | B21: 4. ABRIL | C21: FARMACIA | D21: JUAN TEJADA | E21: 15 | F21: 15 | G21: 15 | H21: 0 | I21: 45 | J21: G016
A22: m894yumy | B22: 4. ABRIL | C22: FARMACIA | D22: JURGEN PALIZA | E22: 15 | F22: 20 | G22: 20 | H22: 25 | I22: 80 | J22: G017
... A40: q98wj818l | B40: 1. ENERO | C40: INACTIVO | D40: ROMARIO QUISPE | E40: 25 | F40: 25 | G40: 25 | H40: 25 | I40: 100 | J40: G011
A41: 1 | B41: 5. MAYO | C41: FARMACIA | D41: MARVIN CASTILLO | E41: 20 | F41: 25 | G41: 25 | H41: 25 | I41: 95 | J41: G008
A42: 2 | B42: 5. MAYO | C42: FARMACIA | D42: JUAN TEJADA | E42: 20 | F42: 20 | I42: 40 | J42: G016
A43: 3 | B43: 5. MAYO | C43: FARMACIA | D43: JURGEN PALIZA | E43: 25 | F43: 25 | G43: 20 | I43: 70 | J43: G017
A44: 4 | B44: 5. MAYO | C44: DHL | D44: ALONSO TAMARA | E44: 20 | F44: 20 | G44: 15 | H44: 15 | I44: 70 | J44: G014
A45: 5 | B45: 5. MAYO | C45: FARMACIA | D45: EDWAR GUERRERO | E45: 15 | F45: 25 | G45: 20 | I45: 60 | J45: G015
A46: 6 | B46: 5. MAYO | C46: FARMACIA | D46: CESAR PLUA | E46: 20 | F46: 20 | G46: 20 | H46: 20 | I46: 80 | J46: G007
A47: 7 | B47: 5. MAYO | C47: INACTIVO | D47: ROMARIO QUISPE | E47: 10 | F47: 20 | G47: 20 | H47: 10 | I47: 60 | J47: G011
A48: 9 | B48: 5. MAYO | C48: DHL | D48: JUAN CARLOS | E48: 15 | F48: 20 | G48: 20 | H48: 15 | I48: 70 | J48: G025
A49: 10 | B49: 5. MAYO | C49: FARMACIA | D49: ANTONIO RIVERA | E49: 20 | F49: 25 | G49: 25 | H49: 25 | I49: 95 | J49: G021
A50: 11 | B50: 5. MAYO | C50: DHL | D50: CHRISTIAN RODRIGUEZ | E50: 20 | F50: 25 | G50: 20 | H50: 20 | I50: 85 | J50: G026
A51: 12 | B51: 5. MAYO | C51: INACTIVO | D51: EDUARDO SANTA CRUZ | E51: 10 | F51: 15 | G51: 10 | I51: 35 | J51: G022
A52: 13 | B52: 6. JUNIO | C52: FARMACIA | D52: MARVIN CASTILLO | E52: 20 | F52: 20 | G52: 20 | H52: 20 | I52: 80 | J52: G008 | K52: Cabina de furgon sucio
A53: 14 | B53: 6. JUNIO | C53: FARMACIA | D53: JUAN TEJADA | E53: 20 | F53: 20 | G53: 20 | H53: 20 | I53: 80 | J53: G016 | K53: Furgone un poco sucio
A54: 15 | B54: 6. JUNIO | C54: DHL | D54: JURGEN PALIZA | E54: 15 | F54: 15 | G54: 20 | H54: 20 | I54: 70 | J54: G017
A55: 16 | B55: 6. JUNIO | C55: DHL | D55: ALONSO TAMARA | E55: 15 | F55: 20 | G55: 20 | H55: 15 | I55: 70 | J55: G014
A56: 17 | B56: 6. JUNIO | C56: FARMACIA | D56: EDWAR GUERRERO | E56: 15 | F56: 15 | G56: 15 | H56: 20 | I56: 65 | J56: G015 | K56: Furgone sucio
A57: 18 | B57: 6. JUNIO | C57: FARMACIA | D57: CESAR PLUA | E57: 20 | F57: 20 | G57: 20 | H57: 20 | I57: 80 | J57: G007 | K57: No llega al 100% porque mezcla los dpc de las farmacias generando sbaglio
...

Sheet AGENDA
A1: ID | B1: DATA | C1: HORA DE INICIO | D1: HORA FIN | E1: RESPONSABLE | F1: COLOR ASIGNADO | G1: PRIORIDAD | H1: TAREA
A2: deb57a19 | B2: 45728 | C2: 0.375 | D2: 0.45833333 | E2: MARTIN | F2: Green | G2: MEDIA | H2: DESPACHAR CONSEGNAS DHL
A3: 01bd08ee | B3: 45728 | C3: 0.5 | D3: 0.58333333 | E3: NATALIA | F3: Orange | G3: MEDIA | H3: ALMUERZO
A4: 37cf386a | B4: 45728 | C4: 0.375 | D4: 0.45833333 | E4: CARLOS | F4: Blue | G4: ALTA | H4: CURSO
A5: 45729.646 | B5: Red | C5: Commercialista/ bilancio , renuovo de contratos
A6: 8d1f5f56 | B6: 45729 | C6: 0.64583333 | D6: 0.70833333 | E6: EMERSON | F6: Red | G6: ALTA | H6: Commercialista
A7: 3031df7f | B7: 45730 | C7: 0.29166667 | D7: 0.41666667 | E7: NATALIA | F7: Orange | G7: ALTA | H7: QUESTURA / PERMESSO DI SOGGIORNO
A8: 7dde7001 | B8: 45730 | C8: 0.29166667 | D8: 0.375 | E8: EMERSON | F8: Red | G8: ALTA | H8: comisaria peschiera
A9: d1621b6a | B9: 45730 | C9: 0.41666667 | D9: 0.5 | E9: EMERSON | F9: Red | G9: ALTA | H9: buscar informacion denuncia contra rabanal
A10: 9c96a51c | B10: 45730 | C10: 0.58333333 | D10: 0.66666667 | E10: EMERSON | F10: Red | G10: MEDIA | H10: comercialista presencias busta pags Ivam
A11: e6535a90 | B11: 45730 | C11: 0.29166667 | D11: 0.33333333 | E11: MARTIN | F11: Green | G11: ALTA | H11: Policia peschiera
A12: 7f988056 | B12: 45734 | C12: 0.39583333 | D12: 0.45833333 | E12: LUIS | F12: Yellow | G12: ALTA | H12: Cambio de vidrio alfa Romeo —- via verona1/a pioltello
A13: 19587c7a | B13: 45735 | C13: 0.64583333 | D13: 0.70833333 | E13: LUIS | F13: Yellow | G13: ALTA | H13: Appuntamento avocado
A14: e4e2b8a2 | B14: 45736 | C14: 0.4375 | D14: 0.54166667 | E14: LUIS | F14: Yellow | G14: ALTA | H14: Cita médica de mi hija debemos ir solo padres
A15: 42e857d1 | B15: 45733 | C15: 0.375 | D15: 0.45833333 | E15: LUIS | F15: Yellow | G15: MEDIA | H15: Marvin no llega al intermedio
A16: 9c641170 | B16: 45732 | C16: 0.16666667 | D16: 0.35416667 | E16: EMERSON | F16: Red | G16: ALTA | H16: Consegna grosseto
A17: 9944b2bf | B17: 45733 | C17: 0.33333333 | D17: 0.4375 | E17: NATALIA | F17: Orange | G17: ALTA | H17: Permesso di soggiorno
... A36: 8e39ccca | B36: 45748 | C36: 0.375 | D36: 0.41666667 | E36: LUIS | F36: Yellow | G36: ALTA | H36: Devolución de furgon GF269YE
A37: 0a760495 | B37: 45748 | C37: 0.45833333 | D37: 0.47222222 | E37: LUIS | F37: Yellow | H37: Devolución del furgón placa GR273XE.que tuvimos por reeemplazo gm089xh
A38: 205dc5d2 | B38: 45738 | C38: 0.33333333 | D38: 0.35416667 | E38: LUIS | F38: Yellow | G38: ALTA | H38: Cambio de furgon gm089xh por guasto. Nos dieron este furgon GR273XE
A39: 0e96fcad | B39: 45750 | C39: 0.4375 | D39: 0.45833333 | E39: LUIS | F39: Yellow | G39: ALTA | H39: Cambio de vetro fm153ve
A40: bbd1aecd | B40: 45749 | C40: 0.54166667 | D40: 0.66666667 | E40: LUIS | F40: Yellow | G40: ALTA | H40: Permesso per documenti julio
A41: 6b5e0e6b | B41: 45755 | C41: 0.43055556 | D41: 0.47222222 | E41: NATALIA | F41: Orange | H41: MEDICO
A42: da7616d3 | B42: 45764 | C42: 0.41666667 | D42: 0.625 | E42: LUIS | F42: Yellow | G42: ALTA | H42: Cita medico inps
A43: 02f7401d | B43: 45796 | C43: 0 | D43: 1 | E43: LUIS | F43: Yellow | G43: ALTA | H43: Vacaciones juan 19 de mayo al 31 MAYO
A44: 9f527128 | B44: 45759 | C44: 0 | D44: 1 | E44: LUIS | F44: Yellow | G44: ALTA | H44: Permesso documento juan tejada
A45: 14ae9963 | B45: 45888 | C45: 0 | D45: 1 | E45: LUIS | F45: Yellow | G45: ALTA | H45: Vacaciones cesar 19/08 al 29/09
A46: 58ff98c4 | B46: 45755 | C46: 0.041666667 | D46: 0.083333333 | E46: MARTIN | F46: Green | G46: ALTA | H46: apuntamento scuola
A47: 4fb3e395 | B47: 45784 | C47: 0.41666667 | D47: 0.41666667 | F47: Blue | G47: BAJA | H47: Cumpleaños Carlos Gamonal
A48: afac0f4f | B48: 45919 | C48: 0.41666667 | D48: 0.41666667 | F48: Blue | G48: BAJA | H48: Cumpleaños Emerson Gamonal
A49: d3725d8e | B49: 46046 | C49: 0.41666667 | D49: 0.41666667 | F49: Blue | G49: BAJA | H49: Cumpleaños Yan Gamonal
A50: a3c23bf4 | B50: 45988 | C50: 0.41666667 | D50: 0.41666667 | F50: Blue | G50: BAJA | H50: Cumpleaños Natalia Plua
A51: 068d079a | B51: 45903 | C51: 0.41666667 | D51: 0.41666667 | F51: Blue | G51: BAJA | H51: Cumple Luis Poma
A52: 3a211881 | B52: 46010 | C52: 0.41666667 | D52: 0.41666667 | F52: Blue | G52: BAJA | H52: Cumple Martin Rodriguez
A53: 75887788 | B53: 45779 | C53: 0.41666667 | D53: 0.41666667 | F53: Blue | G53: BAJA | H53: Cumple Cesar Plua
A54: ba55a3c2 | B54: 45775 | C54: 0.41666667 | D54: 0.41666667 | F54: Blue | G54: BAJA | H54: Cumple Marvin Castillo
A55: c83cd4ff | B55: 46041 | C55: 0.41666667 | D55: 0.41666667 | F55: Blue | G55: BAJA | H55: Cumple Domini Leon
A56: 993bc943 | B56: 45901 | C56: 0.41666667 | D56: 0.41666667 | F56: Blue | G56: BAJA | H56: Cumple Romario Quispe
A58: ce30e677 | B58: 45852 | C58: 0.41666667 | D58: 0.41666667 | F58: Blue | G58: BAJA | H58: Cumple Alonso Tamara
A59: 0f2fd551 | B59: 45850 | C59: 0.41666667 | D59: 0.41666667 | F59: Blue | G59: BAJA | H59: Cumple Edward Guerrero
...

Sheet CALENDARIO AUTISTAS
A1: ID | B1: DATA | C1: HORA DE INICIO | D1: HORA FIN | E1: RESPONSABLE | F1: COLOR ASIGNADO | G1: PRIORIDAD | H1: TAREA
A2: 993debab | B2: 45888 | C2: 0.25694444 | E2: G028 | F2: Blue | H2: Lainate - Genova - Novara - Lainate - DHL.
A3: e4105ddb | F3: Black
A4: f3d72339 | B4: 46007 | C4: 0.54453704 | D4: 0.54453704 | E4: Marvin cerquin | F4: Green | G4: Necesito este dia libre

Sheet CALENDARIO FARMACIA
A1: ID | B1: FECHA | C1: HORA INICIO | D1: HORA FIN | E1: PRIORIDAD | F1: COLOR ASIGNADO | G1: TAREA | H1: DETALLE
A2: 01caf82e | B2: 45896 | C2: 0.18055556 | D2: 0.1875 | E2: ALTA | F2: Green | G2: Horario de ingreso al magazzino
A3: 507bc5ec | B3: 45896 | C3: 0.27777778 | D3: 0.32986111 | E3: ALTA | F3: Yellow | G3: Controlar que todos hayan partido. Verificación del app e actualizaciones.
A4: c2f10277 | B4: 45896 | C4: 0.33333333 | D4: 0.48680556 | E4: ALTA | F4: Red | G4: Cambio de aceite del 032 furgon de juan y llevar a la revisión tecnica. No se pudobrealiza por fallas en el furgon
A5: 9d29414a | B5: 45896 | C5: 0.53125 | D5: 0.125 | E5: ALTA | F5: Yellow | G5: Seguimiento de los giros. Controlar uso de uniforme correctamente. Envio de mail.
A6: 9e84c573 | B6: 45898 | C6: 0.125 | D6: 0.20833333 | E6: ALTA | F6: Red | G6: Diego ultimo dia que puede manejar
A7: 0c55b4dc | B7: 45897 | C7: 0.18055556 | D7: 0.27083333 | E7: ALTA | F7: Green | G7: Seguimiento de giri
A8: 702ff56d | B8: 45897 | C8: 0.33333333 | D8: 0.41666667 | E8: ALTA | F8: Yellow | G8: Revisión tecnica furgon 032
A9: 98f329a9 | B9: 45897 | C9: 0.41666667 | D9: 0.45833333 | E9: MEDIA | F9: Orange | G9: Seguimiento de giri intermedio. Verificación de llaves de giro que esten completas | H9: Verificación de llaves de giro que esten completas
A10: 0afa6d18 | B10: 45897 | C10: 0.47916667 | D10: 0.52013889 | E10: MEDIA | G10: Verificación se la app status vehículos
A11: a8913ec1 | B11: 45897 | C11: 0.54166667 | D11: 0.6875 | E11: ALTA | F11: Red | G11: Seguimiento de giro. Controlar giro 301 y 302
A12: 3111d918 | B12: 45897 | C12: 0.29166667 | D12: 0.33333333 | E12: ALTA | G12: Envio de mail descuentos correspondientes al mes de julio yan.
A13: 6258446a | B13: 45898 | C13: 0.25 | D13: 0.33333333 | E13: ALTA | F13: Green | G13: Verificación del formulario de trabajo diario.
A14: 6f551bf5 | B14: 45898 | C14: 0.33333333 | D14: 0.41666667 | E14: ALTA | G14: Verificación de vehículos limpieza.
A15: c399800d | B15: 45898 | C15: 0.45833333 | D15: 0.52083333 | E15: ALTA | G15: Portar el furgon fy593se al parcheggio de carlos.
A16: 18cc7b6e | B16: 45898 | C16: 0.54166667 | D16: 0.625 | E16: ALTA | F16: Red | G16: Revisión y seguimiento de órdenes y verificación de uso de epp
A17: 2d4cd2f9 | B17: 45897 | C17: 0.41666667 | D17: 0.45833333 | E17: ALTA | F17: Red | G17: Envio de mail de descuentos
A18: 88517ce7 | B18: 45899 | C18: 0.29166667 | D18: 0.375 | E18: ALTA | F18: Red | G18: Verificación de mecánica de vehículos y programación.
A19: b2754fa0 | B19: 45899 | C19: 0.41666667 | D19: 0.5 | E19: ALTA | F19: Red | G19: Verificación del llenado del formulario por el cierre de mes.
A20: 97cd194a | B20: 45899 | C20: 0.54166667 | D20: 0.60416667 | E20: ALTA | G20: Verificación de los giros domingo ya que no tengo todos los vehiculos operativos
A21: aeae2f5a | B21: 45899 | C21: 0.375 | D21: 0.41666667 | E21: MEDIA | F21: Green | G21: Verificación de app. Controllo de velocità e documentos.
A22: 8c4fa4c0 | B22: 45899 | C22: 0.60416667 | D22: 0.66666667 | E22: ALTA | F22: Purple | G22: Detalles de programación para la proxima semana è inizio de mes
A23: 9288ead9 | B23: 45901 | C23: 0.25 | D23: 0.33333333 | E23: ALTA | F23: Red | G23: Verificación de llenado correcto de formulario y depuracion de inconsistencias.
A24: 48f2b533 | B24: 45901 | C24: 0.33402778 | D24: 0.39583333 | E24: ALTA | F24: Red | G24: Verificación de traducción de todos y posibles vencimiento de documentos.
A25: b642c520 | B25: 45901 | C25: 0.41666667 | D25: 0.47916667 | E25: ALTA | F25: Red | G25: Envio de mail. Con inconsistencias
A26: 557319d5 | B26: 45901 | C26: 0.52083333 | D26: 0.10416667 | E26: ALTA | F26: Yellow | G26: Cumplimiento y verificación de uniformes limpios
A27: 5c241775 | B27: 45902 | C27: 0.16666667 | D27: 0.41666667 | E27: ALTA | F27: Red | G27: Cubrir el giro de Romario
A28: a012c3ef | B28: 45902 | C28: 0.54166667 | D28: 0.70833333 | E28: ALTA | F28: Red | G28: Cubrir giro de Romario
A29: 46e90b98 | B29: 45902 | C29: 0.4375 | D29: 0.47916667 | E29: ALTA | F29: Yellow | G29: Intermedio
A30: e0b844e9 | B30: 45903 | C30: 0.16666667 | D30: 0.72916667 | E30: ALTA | F30: Red | G30: Cubrir giro Julio Dioses
A31: 9c9e0f49 | B31: 45903 | C31: 0.41666667 | D31: 0.47916667 | E31: ALTA | G31: Coordinación de renovación de traducción.
A32: 4a145318 | B32: 45903 | C32: 0.72916667 | D32: 0.77083333 | E32: ALTA | F32: Yellow | G32: Verificación dell app, llenado de formulario.
A33: a38259b3 | B33: 45904 | C33: 0.16666667 | D33: 0.4375 | E33: ALTA | G33: Cubrir giro 101 Romario quispe
A34: 874279bd | B34: 45904 | C34: 0.54166667 | D34: 0.70833333 | E34: ALTA | F34: Red | G34: Giro 301 cubrir a Romario quispe
A35: ecadd74c
A36: 0c2f82cc | B36: 45904 | C36: 0.45833333 | D36: 0.54166667 | E36: ALTA | F36: Green | G36: Cita consulado luis poma
A37: 02aeb2a1 | B37: 45905 | C37: 0.27083333 | D37: 0.35416667 | E37: ALTA | F37: Green | G37: Verificación de documentos (traducciones)
